Workbook

Sheet SAP
A1: FECHA | B1: ID TIENDA | C1: NOMBRE | D1: TOTAL VENTA | E1: VISA | F1: EFECTIVO | G1: MASTERCARD | H1: AMERICAN EXPRESS | I1: DINERS | J1: LUKITA (BBVA) | K1: TUNKY (INTERBANK) | L1: WALI (INTERBANK) | M1: YAPE (BCP) | N1: MILLAS INTERBANK | O1: PUNTOS VIDA (BBVA) | P1: TRANSFERENCIA MALVITEC | Q1: RAPPI | R1: ADELANTO (PRE-VENTA) | S1: YAPE (BCP) - 2 | T1: YAPE (BCP) - 3 | U1: SANTANDER | V1: MIS CUOTAS | W1: CUOTEALO | X1: POWERPAY | Y1: CÁLIDDA | Z1: NOTA CREDITO | AA1: TOTAL
A2: 46113 | B2: HON.MS01 | C2: HONOR MALL DEL SUR | D2: 18563.17 | E2: 0 | F2: 747 | G2: 15387.07 | H2: 459 | I2: 0 | J2: 0 | K2: 0 | L2: 0 | M2: 0 | N2: 0 | O2: 0 | P2: 0 | Q2: 0 | R2: 0 | S2: 0 | T2: 0 | U2: 0 | V2: 1970.1 | W2: 0 | X2: 0 | Y2: 0 | Z2: 0 | AA2: 36379.34
A3: 46114 | B3: HON.MS01 | C3: HONOR MALL DEL SUR | D3: 40303.9 | E3: 0 | F3: 3985 | G3: 23291.4 | H3: 3247 | I3: 0 | J3: 0 | K3: 0 | L3: 0 | M3: 0 | N3: 0 | O3: 0 | P3: 0 | Q3: 0 | R3: 0 | S3: 0 | T3: 0 | U3: 0 | V3: 9780.5 | W3: 0 | X3: 0 | Y3: 0 | Z3: 0 | AA3: 76622.8
A4: 46115 | B4: HON.MS01 | C4: HONOR MALL DEL SUR | D4: 15744 | E4: 0 | F4: 688 | G4: 13047.9 | H4: 89 | I4: 0 | J4: 0 | K4: 0 | L4: 0 | M4: 0 | N4: 0 | O4: 0 | P4: 0 | Q4: 0 | R4: 0 | S4: 0 | T4: 0 | U4: 0 | V4: 1919.1 | W4: 0 | X4: 0 | Y4: 0 | Z4: 0 | AA4: 30800
A5: 46116 | B5: HON.MS01 | C5: HONOR MALL DEL SUR | D5: 21848 | E5: 0 | F5: 7937.8 | G5: 12991 | H5: 0 | I5: 0 | J5: 0 | K5: 0 | L5: 0 | M5: 0 | N5: 0 | O5: 0 | P5: 0 | Q5: 0 | R5: 0 | S5: 0 | T5: 0 | U5: 0 | V5: 919.2 | W5: 0 | X5: 0 | Y5: 0 | Z5: 0 | AA5: 35758.2
A6: 46117 | B6: HON.MS01 | C6: HONOR MALL DEL SUR | D6: 25216 | E6: 0 | F6: 7533.8 | G6: 15623 | H6: 0 | I6: 0 | J6: 0 | K6: 0 | L6: 0 | M6: 0 | N6: 0 | O6: 0 | P6: 0 | Q6: 0 | R6: 0 | S6: 0 | T6: 0 | U6: 0 | V6: 2059.2 | W6: 0 | X6: 0 | Y6: 0 | Z6: 0 | AA6: 42898.2
A7: 46118 | B7: HON.MS01 | C7: HONOR MALL DEL SUR | D7: 31530.7 | E7: 0 | F7: 6373.7 | G7: 20075.85 | H7: 0 | I7: 0 | J7: 0 | K7: 0 | L7: 0 | M7: 0 | N7: 0 | O7: 0 | P7: 0 | Q7: 0 | R7: 0 | S7: 0 | T7: 0 | U7: 0 | V7: 5081.15 | W7: 0 | X7: 0 | Y7: 0 | Z7: 0 | AA7: 56687.7
A8: 46119 | B8: HON.MS01 | C8: HONOR MALL DEL SUR | D8: 18051 | E8: 0 | F8: 784 | G8: 14261.5 | H8: 1399 | I8: 0 | J8: 0 | K8: 0 | L8: 0 | M8: 0 | N8: 0 | O8: 0 | P8: 0 | Q8: 0 | R8: 0 | S8: 0 | T8: 0 | U8: 0 | V8: 1606.5 | W8: 0 | X8: 0 | Y8: 0 | Z8: 0 | AA8: 35318
A9: 46120 | B9: HON.MS01 | C9: HONOR MALL DEL SUR | D9: 24613 | E9: 0 | F9: 2697 | G9: 16828.6 | H9: 0 | I9: 0 | J9: 0 | K9: 0 | L9: 0 | M9: 0 | N9: 0 | O9: 0 | P9: 0 | Q9: 0 | R9: 0 | S9: 0 | T9: 0 | U9: 0 | V9: 3938.4 | W9: 0 | X9: 0 | Y9: 1149 | Z9: 0 | AA9: 46529
A10: 46121 | B10: HON.MS01 | C10: HONOR MALL DEL SUR | D10: 18270 | E10: 0 | F10: 3218 | G10: 15052 | H10: 0 | I10: 0 | J10: 0 | K10: 0 | L10: 0 | M10: 0 | N10: 0 | O10: 0 | P10: 0 | Q10: 0 | R10: 0 | S10: 0 | T10: 0 | U10: 0 | V10: 0 | W10: 0 | X10: 0 | Y10: 0 | Z10: 0 | AA10: 33322
A11: 46122 | B11: HON.MS01 | C11: HONOR MALL DEL SUR | D11: 20949 | E11: 0 | F11: 757 | G11: 15721.45 | H11: 0 | I11: 0 | J11: 0 | K11: 0 | L11: 0 | M11: 0 | N11: 0 | O11: 0 | P11: 0 | Q11: 0 | R11: 0 | S11: 0 | T11: 0 | U11: 0 | V11: 3472.55 | W11: 0 | X11: 0 | Y11: 998 | Z11: 0 | AA11: 41141
A12: 46123 | B12: HON.MS01 | C12: HONOR MALL DEL SUR | D12: 40186.4 | E12: 0 | F12: 5224.8 | G12: 29443 | H12: 1399 | I12: 0 | J12: 0 | K12: 0 | L12: 0 | M12: 0 | N12: 0 | O12: 0 | P12: 0 | Q12: 0 | R12: 0 | S12: 0 | T12: 0 | U12: 0 | V12: 4119.6 | W12: 0 | X12: 0 | Y12: 0 | Z12: 0 | AA12: 75148
A13: 46124 | B13: HON.MS01 | C13: HONOR MALL DEL SUR | D13: 35398.9 | E13: 0 | F13: 2689.6 | G13: 25503.5 | H13: 0 | I13: 0 | J13: 0 | K13: 0 | L13: 0 | M13: 0 | N13: 0 | O13: 0 | P13: 0 | Q13: 0 | R13: 0 | S13: 0 | T13: 0 | U13: 0 | V13: 5406.8 | W13: 0 | X13: 0 | Y13: 1799 | Z13: 0 | AA13: 68108.2
... A31: 46142 | B31: HON.MS01 | C31: HONOR MALL DEL SUR | D31: 17745 | E31: 0 | F31: 1447 | G31: 12999.8 | H31: 1699 | I31: 0 | J31: 0 | K31: 0 | L31: 0 | M31: 0 | N31: 0 | O31: 0 | P31: 0 | Q31: 0 | R31: 0 | S31: 0 | T31: 0 | U31: 0 | V31: 1599.2 | W31: 0 | X31: 0 | Y31: 0 | Z31: 0 | AA31: 34043

Sheet REPORTE
A1: FECHA | B1: ID TIENDA | C1: NOMBRE | D1: TOTAL VENTA | E1: VISA | F1: EFECTIVO | G1: DIFERENCIA | H1: MASTERCAD | I1: DIFERENCIA | J1: AMERICAN EXPRESS | K1: DIFERENCIA | L1: DINNERS | M1: DIFERENCIA | N1: LUKITA (BBVA) | O1: TUNKY (INTERBANK) | P1: WALI (INTERBANK) | Q1: YAPE (BCP) | R1: MILLAS INTERBANK | S1: PUNTOS VIDA (BBVA) | T1: TRANSFERENCIA MALVITEC | U1: RAPPI | V1: ADELANTO (PRE-VENTA) | W1: YAPE (BCP) - 2 | X1: YAPE (BCP) - 3 | Y1: SANTANDER | Z1: MIS CUOTAS | AA1: CÁLIDDA | AB1: CUOTEALO | AC1: TOTAL | AD1: NOTA CREDITO
A2: =+SAP!A2 -> 46113 | B2: =+SAP!B2 -> HON.MS01 | C2: =+SAP!C2 -> HONOR MALL DEL SUR | D2: =+SAP!D2 -> 18563.17 | E2: =+SAP!E2 -> 0 | F2: =+SAP!F2 -> 747 | G2: =+F2-SAP!F2 -> 0 | H2: =+SAP!G2 -> 15387.07 | I2: =+H2-MC!AO1 -> 0 | J2: =+SAP!H2 -> 459 | K2: =+J2-AMEX!AI2 -> 0 | L2: =+SAP!I2 -> 0 | M2: =+L2-DINNERS!AI2 -> 0 | N2: =+SAP!J2 -> 0 | O2: =+SAP!K2 -> 0 | P2: =+SAP!L2 -> 0 | Q2: =+SAP!M2 -> 0 | R2: =+SAP!N2 -> 0 | S2: =+SAP!O2 -> 0 | T2: =+SAP!P2 -> 0 | U2: =+SAP!Q2 -> 0 | ... AD2: =+SAP!Z2 -> 0
A3: =+SAP!A3 -> 46114 | B3: =+SAP!B3 -> HON.MS01 | C3: =+SAP!C3 -> HONOR MALL DEL SUR | D3: =+SAP!D3 -> 40303.9 | E3: =+SAP!E3 -> 0 | F3: =+SAP!F3 -> 3985 | G3: =+F3-SAP!F3 -> 0 | H3: =+SAP!G3 -> 23291.4 | I3: =+H3-MC!AO2 -> 0 | J3: =+SAP!H3 -> 3247 | K3: =+J3-AMEX!AI3 -> 0 | L3: =+SAP!I3 -> 0 | M3: =+L3-DINNERS!AI3 -> 0 | N3: =+SAP!J3 -> 0 | O3: =+SAP!K3 -> 0 | P3: =+SAP!L3 -> 0 | Q3: =+SAP!M3 -> 0 | R3: =+SAP!N3 -> 0 | S3: =+SAP!O3 -> 0 | T3: =+SAP!P3 -> 0 | U3: =+SAP!Q3 -> 0 | ... AD3: =+SAP!Z3 -> 0
A4: =+SAP!A4 -> 46115 | B4: =+SAP!B4 -> HON.MS01 | C4: =+SAP!C4 -> HONOR MALL DEL SUR | D4: =+SAP!D4 -> 15744 | E4: =+SAP!E4 -> 0 | F4: =+SAP!F4 -> 688 | G4: =+F4-SAP!F4 -> 0 | H4: =+SAP!G4 -> 13047.9 | I4: =+H4-MC!AO3 -> 498 | J4: =+SAP!H4 -> 89 | K4: =+J4-AMEX!AI4 -> -498 | L4: =+SAP!I4 -> 0 | M4: =+L4-DINNERS!AI4 -> 0 | N4: =+SAP!J4 -> 0 | O4: =+SAP!K4 -> 0 | P4: =+SAP!L4 -> 0 | Q4: =+SAP!M4 -> 0 | R4: =+SAP!N4 -> 0 | S4: =+SAP!O4 -> 0 | T4: =+SAP!P4 -> 0 | U4: =+SAP!Q4 -> 0 | ... AD4: =+SAP!Z4 -> 0
A5: =+SAP!A5 -> 46116 | B5: =+SAP!B5 -> HON.MS01 | C5: =+SAP!C5 -> HONOR MALL DEL SUR | D5: =+SAP!D5 -> 21848 | E5: =+SAP!E5 -> 0 | F5: =+SAP!F5 -> 7937.8 | G5: =+F5-SAP!F5 -> 0 | H5: =+SAP!G5 -> 12991 | I5: =+H5-MC!AO4 -> -75 | J5: =+SAP!H5 -> 0 | K5: =+J5-AMEX!AI5 -> 0 | L5: =+SAP!I5 -> 0 | M5: =+L5-DINNERS!AI5 -> 0 | N5: =+SAP!J5 -> 0 | O5: =+SAP!K5 -> 0 | P5: =+SAP!L5 -> 0 | Q5: =+SAP!M5 -> 0 | R5: =+SAP!N5 -> 0 | S5: =+SAP!O5 -> 0 | T5: =+SAP!P5 -> 0 | U5: =+SAP!Q5 -> 0 | ... AD5: =+SAP!Z5 -> 0
A6: =+SAP!A6 -> 46117 | B6: =+SAP!B6 -> HON.MS01 | C6: =+SAP!C6 -> HONOR MALL DEL SUR | D6: =+SAP!D6 -> 25216 | E6: =+SAP!E6 -> 0 | F6: =+SAP!F6 -> 7533.8 | G6: =+F6-SAP!F6 -> 0 | H6: =+SAP!G6 -> 15623 | I6: =+H6-MC!AO5 -> 0 | J6: =+SAP!H6 -> 0 | K6: =+J6-AMEX!AI6 -> 0 | L6: =+SAP!I6 -> 0 | M6: =+L6-DINNERS!AI6 -> 0 | N6: =+SAP!J6 -> 0 | O6: =+SAP!K6 -> 0 | P6: =+SAP!L6 -> 0 | Q6: =+SAP!M6 -> 0 | R6: =+SAP!N6 -> 0 | S6: =+SAP!O6 -> 0 | T6: =+SAP!P6 -> 0 | U6: =+SAP!Q6 -> 0 | ... AD6: =+SAP!Z6 -> 0
A7: =+SAP!A7 -> 46118 | B7: =+SAP!B7 -> HON.MS01 | C7: =+SAP!C7 -> HONOR MALL DEL SUR | D7: =+SAP!D7 -> 31530.7 | E7: =+SAP!E7 -> 0 | F7: =+SAP!F7 -> 6373.7 | G7: =+F7-SAP!F7 -> 0 | H7: =+SAP!G7 -> 20075.85 | I7: =+H7-MC!AO6 -> 0 | J7: =+SAP!H7 -> 0 | K7: =+J7-AMEX!AI7 -> 0 | L7: =+SAP!I7 -> 0 | M7: =+L7-DINNERS!AI7 -> 0 | N7: =+SAP!J7 -> 0 | O7: =+SAP!K7 -> 0 | P7: =+SAP!L7 -> 0 | Q7: =+SAP!M7 -> 0 | R7: =+SAP!N7 -> 0 | S7: =+SAP!O7 -> 0 | T7: =+SAP!P7 -> 0 | U7: =+SAP!Q7 -> 0 | ... AD7: =+SAP!Z7 -> 0
A8: =+SAP!A8 -> 46119 | B8: =+SAP!B8 -> HON.MS01 | C8: =+SAP!C8 -> HONOR MALL DEL SUR | D8: =+SAP!D8 -> 18051 | E8: =+SAP!E8 -> 0 | F8: =+SAP!F8 -> 784 | G8: =+F8-SAP!F8 -> 0 | H8: =+SAP!G8 -> 14261.5 | I8: =+H8-MC!AO7 -> 0 | J8: =+SAP!H8 -> 1399 | K8: =+J8-AMEX!AI8 -> 0 | L8: =+SAP!I8 -> 0 | M8: =+L8-DINNERS!AI8 -> 0 | N8: =+SAP!J8 -> 0 | O8: =+SAP!K8 -> 0 | P8: =+SAP!L8 -> 0 | Q8: =+SAP!M8 -> 0 | R8: =+SAP!N8 -> 0 | S8: =+SAP!O8 -> 0 | T8: =+SAP!P8 -> 0 | U8: =+SAP!Q8 -> 0 | ... AD8: =+SAP!Z8 -> 0
A9: =+SAP!A9 -> 46120 | B9: =+SAP!B9 -> HON.MS01 | C9: =+SAP!C9 -> HONOR MALL DEL SUR | D9: =+SAP!D9 -> 24613 | E9: =+SAP!E9 -> 0 | F9: =+SAP!F9 -> 2697 | G9: =+F9-SAP!F9 -> 0 | H9: =+SAP!G9 -> 16828.6 | I9: =+H9-MC!AO8 -> 0 | J9: =+SAP!H9 -> 0 | K9: =+J9-AMEX!AI9 -> 0 | L9: =+SAP!I9 -> 0 | M9: =+L9-DINNERS!AI9 -> 0 | N9: =+SAP!J9 -> 0 | O9: =+SAP!K9 -> 0 | P9: =+SAP!L9 -> 0 | Q9: =+SAP!M9 -> 0 | R9: =+SAP!N9 -> 0 | S9: =+SAP!O9 -> 0 | T9: =+SAP!P9 -> 0 | U9: =+SAP!Q9 -> 0 | ... AD9: =+SAP!Z9 -> 0
A10: =+SAP!A10 -> 46121 | B10: =+SAP!B10 -> HON.MS01 | C10: =+SAP!C10 -> HONOR MALL DEL SUR | D10: =+SAP!D10 -> 18270 | E10: =+SAP!E10 -> 0 | F10: =+SAP!F10 -> 3218 | G10: =+F10-SAP!F10 -> 0 | H10: =+SAP!G10 -> 15052 | I10: =+H10-MC!AO9 -> 0 | J10: =+SAP!H10 -> 0 | K10: =+J10-AMEX!AI10 -> 0 | L10: =+SAP!I10 -> 0 | M10: =+L10-DINNERS!AI10 -> 0 | N10: =+SAP!J10 -> 0 | O10: =+SAP!K10 -> 0 | P10: =+SAP!L10 -> 0 | Q10: =+SAP!M10 -> 0 | R10: =+SAP!N10 -> 0 | S10: =+SAP!O10 -> 0 | T10: =+SAP!P10 -> 0 | U10: =+SAP!Q10 -> 0 | ... AD10: =+SAP!Z10 -> 0
A11: =+SAP!A11 -> 46122 | B11: =+SAP!B11 -> HON.MS01 | C11: =+SAP!C11 -> HONOR MALL DEL SUR | D11: =+SAP!D11 -> 20949 | E11: =+SAP!E11 -> 0 | F11: =+SAP!F11 -> 757 | G11: =+F11-SAP!F11 -> 0 | H11: =+SAP!G11 -> 15721.45 | I11: =+H11-MC!AO10 -> 2148 | J11: =+SAP!H11 -> 0 | K11: =+J11-AMEX!AI11 -> -2148 | L11: =+SAP!I11 -> 0 | M11: =+L11-DINNERS!AI11 -> 0 | N11: =+SAP!J11 -> 0 | O11: =+SAP!K11 -> 0 | P11: =+SAP!L11 -> 0 | Q11: =+SAP!M11 -> 0 | R11: =+SAP!N11 -> 0 | S11: =+SAP!O11 -> 0 | T11: =+SAP!P11 -> 0 | U11: =+SAP!Q11 -> 0 | ... AD11: =+SAP!Z11 -> 0
A12: =+SAP!A12 -> 46123 | B12: =+SAP!B12 -> HON.MS01 | C12: =+SAP!C12 -> HONOR MALL DEL SUR | D12: =+SAP!D12 -> 40186.4 | E12: =+SAP!E12 -> 0 | F12: =+SAP!F12 -> 5224.8 | G12: =+F12-SAP!F12 -> 0 | H12: =+SAP!G12 -> 29443 | I12: =+H12-MC!AO11 -> 0 | J12: =+SAP!H12 -> 1399 | K12: =+J12-AMEX!AI12 -> 0 | L12: =+SAP!I12 -> 0 | M12: =+L12-DINNERS!AI12 -> 0 | N12: =+SAP!J12 -> 0 | O12: =+SAP!K12 -> 0 | P12: =+SAP!L12 -> 0 | Q12: =+SAP!M12 -> 0 | R12: =+SAP!N12 -> 0 | S12: =+SAP!O12 -> 0 | T12: =+SAP!P12 -> 0 | U12: =+SAP!Q12 -> 0 | ... AD12: =+SAP!Z12 -> 0
A13: =+SAP!A13 -> 46124 | B13: =+SAP!B13 -> HON.MS01 | C13: =+SAP!C13 -> HONOR MALL DEL SUR | D13: =+SAP!D13 -> 35398.9 | E13: =+SAP!E13 -> 0 | F13: =+SAP!F13 -> 2689.6 | G13: =+F13-SAP!F13 -> 0 | H13: =+SAP!G13 -> 25503.5 | I13: =+H13-MC!AO12 -> 0 | J13: =+SAP!H13 -> 0 | K13: =+J13-AMEX!AI13 -> 0 | L13: =+SAP!I13 -> 0 | M13: =+L13-DINNERS!AI13 -> 0 | N13: =+SAP!J13 -> 0 | O13: =+SAP!K13 -> 0 | P13: =+SAP!L13 -> 0 | Q13: =+SAP!M13 -> 0 | R13: =+SAP!N13 -> 0 | S13: =+SAP!O13 -> 0 | T13: =+SAP!P13 -> 0 | U13: =+SAP!Q13 -> 0 | ... AD13: =+SAP!Z13 -> 0
... A31: =+SAP!A31 -> 46142 | B31: =+SAP!B31 -> HON.MS01 | C31: =+SAP!C31 -> HONOR MALL DEL SUR | D31: =+SAP!D31 -> 17745 | E31: =+SAP!E31 -> 0 | F31: =+SAP!F31 -> 1447 | G31: =+F31-SAP!F31 -> 0 | H31: =+SAP!G31 -> 12999.8 | I31: =+H31-MC!AO30 -> 12999.8 | J31: =+SAP!H31 -> 1699 | K31: =+J31-AMEX!AI31 -> 1699 | L31: =+SAP!I31 -> 0 | M31: =+L31-DINNERS!AI31 -> 0 | N31: =+SAP!J31 -> 0 | O31: =+SAP!K31 -> 0 | P31: =+SAP!L31 -> 0 | Q31: =+SAP!M31 -> 0 | R31: =+SAP!N31 -> 0 | S31: =+SAP!O31 -> 0 | T31: =+SAP!P31 -> 0 | U31: =+SAP!Q31 -> 0 | ... AD31: =+SAP!Z31 -> 0

Sheet EFECTIVO
E2: CODIGO COMERCIO | F2: 1030313
B4: FECHA | C4: EFECTIVO | D4: F. Operación | E4: Nº. Doc. | F4: Concepto | G4: Importe | H4: DIFERENCIA | I4: OBS | J4: BANCO | K4: ESTADO | L4: CONTAB.
B5: =+SAP!A2 -> 46113 | C5: =+SAP!F2 -> 747 | D5: 45691 | E5: 0000253257 | F5: INGRESO EN EFECTIVO | G5: 15478.8 | H5: =SUM(C37:C41)+C5-G5 -> -4499.69 | J5: 104101 | K5: OK | L5: OK | Q5: =+B5 -> 46113 | R5: =+C5 -> 747
B6: =+SAP!A3 -> 46114 | C6: =+SAP!F3 -> 3985 | D6: 45693 | E6: 0000253862 | F6: MARTIN ALONSO CONCHA ALCALA | G6: 3570.5 | H6: =SUM(C6:C8)-G6 -> 9040.3 | J6: 104101 | K6: OK | L6: OK | Q6: =+B6 -> 46114 | R6: =+C6 -> 3985
B7: =+SAP!A4 -> 46115 | C7: =+SAP!F4 -> 688 | Q7: =+B7 -> 46115 | R7: =+C7 -> 688
B8: =+SAP!A5 -> 46116 | C8: =+SAP!F5 -> 7937.8 | Q8: =+B8 -> 46116 | R8: =+C8 -> 7937.8
B9: =+SAP!A6 -> 46117 | C9: =+SAP!F6 -> 7533.8 | D9: 45696 | E9: 0000254289 | F9: INGRESO EN EFECTIVO | G9: 4593.7 | H9: =+C9+C10-G9 -> 9313.8 | J9: 104101 | K9: OK | L9: OK | Q9: =+B9 -> 46117 | R9: =+C9 -> 7533.8
B10: =+SAP!A7 -> 46118 | C10: =+SAP!F7 -> 6373.7 | Q10: =+B10 -> 46118 | R10: =+C10 -> 6373.7
B11: =+SAP!A8 -> 46119 | C11: =+SAP!F8 -> 784 | D11: 45698 | E11: 0000254326 | F11: INGRESO EN EFECTIVO | G11: 6645.1 | H11: =+C11+C12-G11 -> -3164.1 | J11: 104101 | K11: OK | L11: OK | Q11: =+B11 -> 46119 | R11: =+C11 -> 784
B12: =+SAP!A9 -> 46120 | C12: =+SAP!F9 -> 2697 | Q12: =+B12 -> 46120 | R12: =+C12 -> 2697
B13: =+SAP!A10 -> 46121 | C13: =+SAP!F10 -> 3218 | D13: 45700 | E13: 0000255219 | F13: INGRESO EN EFECTIVO | G13: 10567.2 | H13: =SUM(C13:C15)-G13 -> -1367.4 | J13: 104101 | K13: OK | L13: OK | Q13: =+B13 -> 46121 | R13: =+C13 -> 3218
B14: =+SAP!A11 -> 46122 | C14: =+SAP!F11 -> 757 | Q14: =+B14 -> 46122 | R14: =+C14 -> 757
B15: =+SAP!A12 -> 46123 | C15: =+SAP!F12 -> 5224.8 | Q15: =+B15 -> 46123 | R15: =+C15 -> 5224.8
B16: =+SAP!A13 -> 46124 | C16: =+SAP!F13 -> 2689.6 | D16: 45705 | E16: 0000255733 | F16: INGRESO EN EFECTIVO | G16: 8725.8 | H16: =SUM(C16:C19)-G16 -> -1218.2 | J16: 104101 | K16: OK | L16: OK | M16: AMEX- SE HIZO DEVOLUCION CLIENTE EFECTIVO PORQUE NO SE PUDO ANULAR | Q16: =+B16 -> 46124 | R16: =+C16 -> 2689.6
B17: =+SAP!A14 -> 46125 | C17: =+SAP!F14 -> 629 | Q17: =+B17 -> 46125 | R17: =+C17 -> 629
B18: =+SAP!A15 -> 46126 | C18: =+SAP!F15 -> 3890 | Q18: =+B18 -> 46126 | R18: =+C18 -> 3890
B19: =+SAP!A16 -> 46127 | C19: =+SAP!F16 -> 299 | Q19: =+B19 -> 46127 | R19: =+C19 -> 299
B20: =+SAP!A17 -> 46128 | C20: =+SAP!F17 -> 2362.9 | D20: 45707 | E20: 0000256679 | F20: INGRESO EN EFECTIVO | G20: 4670.1 | H20: =SUM(C20:C22)-G20 -> 10050.6 | K20: OK | L20: OK | Q20: =+B20 -> 46128 | R20: =+C20 -> 2362.9
B21: =+SAP!A18 -> 46129 | C21: =+SAP!F18 -> 2945 | Q21: =+B21 -> 46129 | R21: =+C21 -> 2945
B22: =+SAP!A19 -> 46130 | C22: =+SAP!F19 -> 9412.8 | Q22: =+B22 -> 46130 | R22: =+C22 -> 9412.8
B23: =+SAP!A20 -> 46131 | C23: =+SAP!F20 -> 5371.6 | D23: 45709 | E23: 0000257081 | F23: INGRESO EN EFECTIVO | G23: 6883.6 | H23: =+C23+C24-G23 -> 1459.9 | K23: OK | L23: OK | Q23: =+B23 -> 46131 | R23: =+C23 -> 5371.6
B24: =+SAP!A21 -> 46132 | C24: =+SAP!F21 -> 2971.9 | Q24: =+B24 -> 46132 | R24: =+C24 -> 2971.9
B25: =+SAP!A22 -> 46133 | C25: =+SAP!F22 -> 4803 | D25: 45712 | E25: 0000257459 | F25: INGRESO EN EFECTIVO | G25: 14300.6 | H25: =SUM(C25:C27)-G25 -> -2596.1 | K25: OK | L25: OK | Q25: =+B25 -> 46133 | R25: =+C25 -> 4803
B26: =+SAP!A23 -> 46134 | C26: =+SAP!F23 -> 3278.7 | Q26: =+B26 -> 46134 | R26: =+C26 -> 3278.7
B27: =+SAP!A24 -> 46135 | C27: =+SAP!F24 -> 3622.8 | Q27: =+B27 -> 46135 | R27: =+C27 -> 3622.8
B28: =+SAP!A25 -> 46136 | C28: =+SAP!F25 -> 2676 | D28: 45714 | E28: 0000257935 | F28: INGRESO EN EFECTIVO | G28: 5858.6 | H28: =+C28+C29-G28 -> 3109.2 | K28: OK | L28: OK | Q28: =+B28 -> 46136 | R28: =+C28 -> 2676
B29: =+SAP!A26 -> 46137 | C29: =+SAP!F26 -> 6291.8 | Q29: =+B29 -> 46137 | R29: =+C29 -> 6291.8
B30: =+SAP!A27 -> 46138 | C30: =+SAP!F27 -> 4845.8 | H30: =+C30-G30 -> 4845.8 | K30: PENDIENTE | L30: MARZO | Q30: =+B30 -> 46138 | R30: =+C30 -> 4845.8
B31: =+SAP!A28 -> 46139 | C31: =+SAP!F28 -> 6946 | H31: =+C31-G31 -> 6946 | K31: PENDIENTE | L31: MARZO | Q31: =+B31 -> 46139 | R31: =+C31 -> 6946
B32: =+SAP!A29 -> 46140 | C32: =+SAP!F29 -> 6368.8 | H32: =+C32-G32 -> 6368.8 | K32: PENDIENTE | L32: MARZO | Q32: =+B32 -> 46140 | R32: =+C32 -> 6368.8
B33: =+SAP!A30 -> 46141 | C33: =+SAP!F30 -> 279 | H33: =+C33-G33 -> 279 | Q33: =+B33 -> 46141 | R33: =+C33 -> 279
B34: =+SAP!A31 -> 46142 | C34: =+SAP!F31 -> 1447 | H34: =+C34-G34 -> 1447 | Q34: =+B34 -> 46142 | R34: =+C34 -> 1447
B35: =+SAP!A32 -> 0 | C35: =+SAP!F32 -> 0 | H35: =+C35-G35 -> 0 | Q35: =+B35 -> 0 | R35: =+C35 -> 0
B37: 45684 | C37: 2494 | H37: 2494 | K37: OK | L37: FEBRERO
B38: 45685 | C38: 854.7 | H38: 854.7 | K38: OK | L38: FEBRERO
B39: 45686 | C39: 1856.19 | H39: 1856.19 | K39: OK | L39: FEBRERO
B40: 45687 | C40: 1520.9 | H40: 1520.9 | K40: OK | L40: FEBRERO
B41: 45688 | C41: 3506.32 | H41: 3506.32 | K41: OK | L41: FEBRERO
F43: TOTAL PENDIENTE | G43: =SUMIF(K5:K38,"PENDIENTE",C5:C38) -> 18160.6
D46: F. Operación | E46: Nº. Doc. | F46: Concepto | G46: Importe | H46: TIENDA | I46: FECHA
...

Sheet MC
A1: Codigo | B1: Producto | C1: Tipo_Mov | D1: Fecha_Proceso | E1: Fecha_Lote | F1: Lote_Manual | G1: Lote_Pos | H1: Terminal | I1: Voucher | J1: Autorizacion | K1: Cuotas | L1: Tarjeta | M1: Origen | N1: Transaccion | O1: Fecha_Consumo | P1: Importe | Q1: Status | R1: Comision | S1: Comision_Afecta | T1: IGV | U1: Neto_Parcial | V1: Neto_Total | W1: Fecha_Abono | X1: Fecha_Abono_8Dig | Y1: Observaciones | Z1: Tipo_Tarjeta | AA1: Serie_Terminal | AB1: Banco_Emisor | AC1: Cuota sin interes | AD1: Entidad | AE1: Hora TRX | AF1: Nombre comercial | AG1: BANCO | AJ1: Etiquetas de fila | AK1: Suma de Importe | AN1: 46082 | AO1: 15387.07
A2: 1044162 | B2: MC | C2: A | D2: 46113 | E2: 46113 | G2: 870 | H2: PS0002 | I2: 2960 | J2: 81258 | K2: 3 | L2: 553650******2982 | M2: Nac | N2: COM | O2: 46113 | P2: 1248 | Q2: Abonado | R2: 57.91 | S2: 4.25 | T2: 0.77 | U2: 1189.32 | V2: 1189.32 | W2: 46118 | X2: 20260406 | Y2: 104101 | Z2: CREDITO | AA2: 3908900 | AB2: BBVA | AC2: SI | AE2: 0.55163194 | AF2: HONOR MALL DEL SUR | AG2: BBVA | AJ2: 46113 | AK2: 15387.07 | AN2: =+AN1+1 -> 46083 | AO2: 23291.4
A3: 1044162 | B3: VA | C3: A | D3: 46113 | E3: 46113 | G3: 870 | H3: PS0002 | I3: 2958 | J3: 266228 | L3: 455788******8285 | M3: Nac | N3: COM | O3: 46113 | P3: 448.9 | Q3: Abonado | R3: 12.97 | S3: 5.79 | T3: 1.04 | U3: 434.89 | V3: 0 | X3: 20260406 | Z3: DEBITO | AA3: 3908900 | AB3: BCP | AE3: 0.53292824 | AF3: HONOR MALL DEL SUR | AG3: BBVA | AJ3: 46114 | AK3: 23291.4 | AN3: =+AN2+1 -> 46084 | AO3: 12549.9
A4: 1044162 | B4: VA | C4: A | D4: 46113 | E4: 46113 | G4: 870 | H4: PS0002 | I4: 2963 | J4: 8897 | L4: 463401******5458 | M4: Nac | N4: COM | O4: 46113 | P4: 4999 | Q4: Abonado | R4: 144.47 | S4: 39.49 | T4: 7.11 | U4: 4847.42 | V4: 0 | X4: 20260406 | Z4: CREDITO | AA4: 3908900 | AB4: BCP | AE4: 0.55978009 | AF4: HONOR MALL DEL SUR | AG4: BBVA | AJ4: 46115 | AK4: 12549.9 | AN4: =+AN3+1 -> 46085 | AO4: 13066
A5: 1044162 | B5: VA | C5: A | D5: 46113 | E5: 46113 | G5: 870 | H5: PS0002 | I5: 2965 | J5: 877095 | L5: 455788******2216 | M5: Nac | N5: COM | O5: 46113 | P5: 429 | Q5: Abonado | R5: 12.4 | S5: 5.54 | T5: 1 | U5: 415.6 | V5: 0 | X5: 20260406 | Z5: DEBITO | AA5: 3908900 | AB5: BCP | AE5: 0.56869213 | AF5: HONOR MALL DEL SUR | AG5: BBVA | AJ5: 46116 | AK5: 13066 | AN5: =+AN4+1 -> 46086 | AO5: 15623
A6: 1044162 | B6: VA | C6: A | D6: 46113 | E6: 46113 | G6: 870 | H6: PS0002 | I6: 2967 | J6: 309566 | L6: 455788******8980 | M6: Nac | N6: COM | O6: 46113 | P6: 149 | Q6: Abonado | R6: 4.31 | S6: 1.93 | T6: 0.35 | U6: 144.34 | V6: 0 | X6: 20260406 | Z6: DEBITO | AA6: 3908900 | AB6: BCP | AE6: 0.5765625 | AF6: HONOR MALL DEL SUR | AG6: BBVA | AJ6: 46117 | AK6: 15623 | AN6: =+AN5+1 -> 46087 | AO6: 20075.85
A7: 1044162 | B7: VA | C7: A | D7: 46113 | E7: 46113 | G7: 870 | H7: PS0002 | I7: 2969 | J7: 23243 | L7: 407067******9255 | M7: Nac | N7: COM | O7: 46113 | P7: 629 | Q7: Abonado | R7: 18.18 | S7: 3.71 | T7: 0.67 | U7: 610.15 | V7: 0 | X7: 20260406 | Z7: CREDITO | AA7: 3908900 | AB7: SCOTIABANK | AE7: 0.61023148 | AF7: HONOR MALL DEL SUR | AG7: BBVA | AJ7: 46118 | AK7: 20075.85 | AN7: =+AN6+1 -> 46088 | AO7: 14261.5
A8: 1044162 | B8: VA | C8: A | D8: 46113 | E8: 46113 | G8: 870 | H8: PS0002 | I8: 2973 | J8: 514762 | L8: 455788******9917 | M8: Nac | N8: COM | O8: 46113 | P8: 1699 | Q8: Abonado | R8: 49.1 | S8: 21.92 | T8: 3.95 | U8: 1645.95 | V8: 0 | X8: 20260406 | Z8: DEBITO | AA8: 3908900 | AB8: BCP | AE8: 0.62674769 | AF8: HONOR MALL DEL SUR | AG8: BBVA | AJ8: 46119 | AK8: 14261.5 | AN8: =+AN7+1 -> 46089 | AO8: 16828.6
A9: 1044162 | B9: VA | C9: A | D9: 46113 | E9: 46113 | G9: 870 | H9: PS0002 | I9: 2984 | J9: 715830 | L9: 455788******7152 | M9: Nac | N9: COM | O9: 46113 | P9: 63 | Q9: Abonado | R9: 1.82 | S9: 0.81 | T9: 0.15 | U9: 61.03 | V9: 0 | X9: 20260406 | Z9: DEBITO | AA9: 3908900 | AB9: BCP | AE9: 0.73603009 | AF9: HONOR MALL DEL SUR | AG9: BBVA | AJ9: 46120 | AK9: 16828.6 | AN9: =+AN8+1 -> 46090 | AO9: 15052
A10: 1044162 | B10: VA | C10: A | D10: 46113 | E10: 46113 | G10: 870 | H10: PS0002 | I10: 2986 | J10: 174143 | L10: 483039******9147 | M10: Nac | N10: COM | O10: 46113 | P10: 566 | Q10: Abonado | R10: 16.36 | S10: 4.47 | T10: 0.8 | U10: 548.84 | V10: 0 | X10: 20260406 | Z10: DEBITO | AA10: 3908900 | AB10: IBK PRIVADA | AE10: 0.73655093 | AF10: HONOR MALL DEL SUR | AG10: BBVA | AJ10: 46121 | AK10: 15052 | AN10: =+AN9+1 -> 46091 | AO10: 13573.45
A11: 1044162 | B11: VA | C11: A | D11: 46113 | E11: 46113 | G11: 870 | H11: PS0002 | I11: 2988 | J11: 355874 | L11: 414791******4610 | M11: Nac | N11: COM | O11: 46113 | P11: 1149 | Q11: Abonado | R11: 33.21 | S11: 6.78 | T11: 1.22 | U11: 1114.57 | V11: 0 | X11: 20260406 | Z11: CREDITO | AA11: 3908900 | AB11: BBVA | AE11: 0.77609954 | AF11: HONOR MALL DEL SUR | AG11: BBVA | AJ11: 46122 | AK11: 13573.45 | AN11: =+AN10+1 -> 46092 | AO11: 29443
A12: 1044162 | B12: VA | C12: A | D12: 46113 | E12: 46113 | G12: 870 | H12: PS0002 | I12: 2992 | J12: 899964 | L12: 455788******3937 | M12: Nac | N12: COM | O12: 46113 | P12: 629 | Q12: Abonado | R12: 18.18 | S12: 8.12 | T12: 1.46 | U12: 609.36 | V12: 0 | X12: 20260406 | Z12: DEBITO | AA12: 3908900 | AB12: BCP | AE12: 0.79758102 | AF12: HONOR MALL DEL SUR | AG12: BBVA | AJ12: 46123 | AK12: 29443 | AN12: =+AN11+1 -> 46093 | AO12: 25503.5
A13: 1044162 | B13: VA | C13: A | D13: 46113 | E13: 46113 | G13: 870 | H13: PS0002 | I13: 2995 | J13: 118963 | L13: 421410******1826 | M13: Nac | N13: COM | O13: 46113 | P13: 459 | Q13: Abonado | R13: 13.27 | S13: 5.93 | T13: 1.07 | U13: 444.66 | V13: 0 | X13: 20260406 | Z13: DEBITO | AA13: 3908900 | AB13: NACION | AE13: 0.83293981 | AF13: HONOR MALL DEL SUR | AG13: BBVA | AJ13: 46124 | AK13: 25503.5 | AN13: =+AN12+1 -> 46094 | AO13: 10947.5
A14: 1044162 | B14: VA | C14: A | D14: 46113 | E14: 46113 | G14: 870 | H14: PS0002 | I14: 2997 | J14: 200306 | L14: 483039******9147 | M14: Nac | N14: COM | O14: 46113 | P14: 1000 | Q14: Abonado | R14: 28.9 | S14: 7.9 | T14: 1.42 | U14: 969.68 | V14: 0 | X14: 20260406 | Z14: DEBITO | AA14: 3908900 | AB14: IBK PRIVADA | AE14: 0.8347338 | AF14: HONOR MALL DEL SUR | AG14: BBVA | AJ14: 46125 | AK14: 10947.5 | AN14: =+AN13+1 -> 46095 | AO14: 16358.9
A15: 1044162 | B15: VA | C15: A | D15: 46113 | E15: 46113 | G15: 870 | H15: PS0002 | I15: 3000 | J15: 31007 | L15: 424303******2403 | M15: Nac | N15: COM | O15: 46113 | P15: 31.17 | Q15: Abonado | R15: 0.9 | S15: 0.4 | T15: 0.07 | U15: 30.2 | V15: 0 | X15: 20260406 | Z15: DEBITO | AA15: 3908900 | AB15: VISA LOC | AE15: 0.85583333 | AF15: HONOR MALL DEL SUR | AG15: BBVA | AJ15: 46126 | AK15: 16358.9 | AN15: =+AN14+1 -> 46096 | AO15: 8952.8
A16: 1044162 | B16: VA | C16: A | D16: 46113 | E16: 46113 | G16: 870 | H16: PS0002 | I16: 3002 | J16: 178615 | L16: 491909******4952 | M16: Nac | N16: COM | O16: 46113 | P16: 89 | Q16: Abonado | R16: 2.57 | S16: 0.7 | T16: 0.13 | U16: 86.3 | V16: 11962.99 | W16: 46118 | X16: 20260406 | Y16: 104101 | Z16: CREDITO | AA16: 3908900 | AB16: BBVA | AE16: 0.91415509 | AF16: HONOR MALL DEL SUR | AG16: BBVA | AJ16: 46127 | AK16: 8952.8 | AN16: =+AN15+1 -> 46097 | AO16: 4074.9
A17: 1044162 | B17: VK | C17: A | D17: 46113 | E17: 46113 | G17: 870 | H17: PS0002 | I17: 2971 | J17: 53609 | L17: 404071******5793 | M17: Nac | N17: COM | O17: 46113 | P17: 1799 | Q17: Abonado | R17: 51.99 | S17: 14.21 | T17: 2.56 | U17: 1744.45 | V17: 1744.45 | W17: 46118 | X17: 20260406 | Y17: 104101 | Z17: CREDITO | AA17: 3908900 | AB17: SIP MC | AE17: 0.61662037 | AF17: HONOR MALL DEL SUR | AG17: BBVA | AJ17: 46128 | AK17: 4074.9 | AN17: =+AN16+1 -> 46098 | AO17: 5120.75
A18: 1044162 | B18: VA | C18: A | D18: 46114 | E18: 46114 | G18: 871 | H18: PS0002 | I18: 3007 | J18: 745542 | L18: 421355******2349 | M18: Nac | N18: COM | O18: 46114 | P18: 229.8 | Q18: Abonado | R18: 6.64 | S18: 2.96 | T18: 0.53 | U18: 222.63 | V18: 0 | X18: 20260406 | Z18: DEBITO | AA18: 3908900 | AB18: IBK PRIVADA | AE18: 0.43244213 | AF18: HONOR MALL DEL SUR | AG18: BBVA | AJ18: 46129 | AK18: 5120.75 | AN18: =+AN17+1 -> 46099 | AO18: 10307
A19: 1044162 | B19: VA | C19: A | D19: 46114 | E19: 46114 | G19: 871 | H19: PS0002 | I19: 3009 | J19: 709926 | L19: 455788******5232 | M19: Nac | N19: COM | O19: 46114 | P19: 798.9 | Q19: Abonado | R19: 23.09 | S19: 10.31 | T19: 1.86 | U19: 773.95 | V19: 0 | X19: 20260406 | Z19: DEBITO | AA19: 3908900 | AB19: BCP | AE19: 0.50273148 | AF19: HONOR MALL DEL SUR | AG19: BBVA | AJ19: 46130 | AK19: 10307 | AN19: =+AN18+1 -> 46100 | AO19: 19100
A20: 1044162 | B20: VA | C20: A | D20: 46114 | E20: 46114 | G20: 871 | H20: PS0002 | I20: 3015 | J20: 913723 | L20: 455788******6834 | M20: Nac | N20: COM | O20: 46114 | P20: 1248 | Q20: Abonado | R20: 36.07 | S20: 16.1 | T20: 2.9 | U20: 1209.03 | V20: 0 | X20: 20260406 | Z20: DEBITO | AA20: 3908900 | AB20: BCP | AE20: 0.59326389 | AF20: HONOR MALL DEL SUR | AG20: BBVA | AJ20: 46131 | AK20: 19100 | AN20: =+AN19+1 -> 46101 | AO20: 8209.7
A21: 1044162 | B21: VA | C21: A | D21: 46114 | E21: 46114 | G21: 871 | H21: PS0002 | I21: 3017 | J21: 178502 | L21: 455170******4842 | M21: Nac | N21: COM | O21: 46114 | P21: 179.9 | Q21: Abonado | R21: 5.2 | S21: 2.32 | T21: 0.42 | U21: 174.28 | V21: 0 | X21: 20260406 | Z21: DEBITO | AA21: 3908900 | AB21: BBVA | AE21: 0.61331019 | AF21: HONOR MALL DEL SUR | AG21: BBVA | AJ21: 46132 | AK21: 8209.7 | AN21: =+AN20+1 -> 46102
A22: 1044162 | B22: VA | C22: A | D22: 46114 | E22: 46114 | G22: 871 | H22: PS0002 | I22: 3028 | J22: 478383 | L22: 404293******1375 | M22: Nac | N22: COM | O22: 46114 | P22: 500 | Q22: Abonado | R22: 14.45 | S22: 3.95 | T22: 0.71 | U22: 484.84 | V22: 0 | X22: 20260406 | Z22: CREDITO | AA22: 3908900 | AB22: BBVA | AE22: 0.67898148 | AF22: HONOR MALL DEL SUR | AG22: BBVA | AJ22: Total general | AK22: 297726.82 | AN22: =+AN21+1 -> 46103
A23: 1044162 | B23: VA | C23: A | D23: 46114 | E23: 46114 | G23: 871 | H23: PS0002 | I23: 3030 | J23: 7967 | L23: 407876******9543 | M23: Nac | N23: COM | O23: 46114 | P23: 1238 | Q23: Abonado | R23: 35.78 | S23: 7.31 | T23: 1.32 | U23: 1200.9 | V23: 0 | X23: 20260406 | Z23: CREDITO | AA23: 3908900 | AB23: BFALABELLA | AE23: 0.68465278 | AF23: HONOR MALL DEL SUR | AG23: BBVA | AN23: =+AN22+1 -> 46104
A24: 1044162 | B24: VA | C24: A | D24: 46114 | E24: 46114 | G24: 871 | H24: 65656565 | I24: 3032 | J24: 207848 | L24: 455788******9787 | M24: Nac | N24: COM | O24: 46114 | P24: 500 | Q24: Abonado | R24: 14.45 | S24: 6.45 | T24: 1.16 | U24: 484.39 | V24: 0 | X24: 20260406 | Z24: DEBITO | AA24: 3908900 | AB24: BCP | AD24: Yape | AE24: 0.71100694 | AF24: HONOR MALL DEL SUR | AG24: BBVA | AN24: =+AN23+1 -> 46105
A25: 1044162 | B25: VA | C25: A | D25: 46114 | E25: 46114 | G25: 871 | H25: 65656565 | I25: 3035 | J25: 177500 | L25: 455788******9787 | M25: Nac | N25: COM | O25: 46114 | P25: 500 | Q25: Abonado | R25: 14.45 | S25: 6.45 | T25: 1.16 | U25: 484.39 | V25: 0 | X25: 20260406 | Z25: DEBITO | AA25: 3908900 | AB25: BCP | AD25: Yape | AE25: 0.7115162 | AF25: HONOR MALL DEL SUR | AG25: BBVA | AN25: =+AN24+1 -> 46106
A26: 1044162 | B26: VA | C26: A | D26: 46114 | E26: 46114 | G26: 871 | H26: 65656565 | I26: 3038 | J26: 178388 | L26: 455788******9787 | M26: Nac | N26: COM | O26: 46114 | P26: 248 | Q26: Abonado | R26: 7.16 | S26: 3.19 | T26: 0.57 | U26: 240.27 | V26: 0 | X26: 20260406 | Z26: DEBITO | AA26: 3908900 | AB26: BCP | AD26: Yape | AE26: 0.7119213 | AF26: HONOR MALL DEL SUR | AG26: BBVA | AN26: =+AN25+1 -> 46107
A27: 1044162 | B27: VA | C27: A | D27: 46114 | E27: 46114 | G27: 871 | H27: PS0002 | I27: 3041 | J27: 638357 | K27: 3 | L27: 414791******2720 | M27: Nac | N27: COM | O27: 46114 | P27: 949 | Q27: Abonado | R27: 44.04 | S27: 5.6 | T27: 1.01 | U27: 903.95 | V27: 0 | X27: 20260406 | Z27: CREDITO | AA27: 3908900 | AB27: BBVA | AC27: SI | AE27: 0.71458333 | AF27: HONOR MALL DEL SUR | AG27: BBVA | AN27: =+AN26+1 -> 46108
A28: 1044162 | B28: VA | C28: A | D28: 46114 | E28: 46114 | G28: 871 | H28: 65656565 | I28: 3043 | J28: 274117 | L28: 455788******4900 | M28: Nac | N28: COM | O28: 46114 | P28: 89 | Q28: Abonado | R28: 2.57 | S28: 1.15 | T28: 0.21 | U28: 86.22 | V28: 0 | X28: 20260406 | Z28: DEBITO | AA28: 3908900 | AB28: BCP | AD28: Yape | AE28: 0.7447338 | AF28: HONOR MALL DEL SUR | AG28: BBVA | AN28: =+AN27+1 -> 46109
A29: 1044162 | B29: VA | C29: A | D29: 46114 | E29: 46114 | G29: 871 | H29: PS0002 | I29: 3046 | J29: 919758 | L29: 455170******6354 | M29: Nac | N29: COM | O29: 46114 | P29: 949 | Q29: Abonado | R29: 27.43 | S29: 12.25 | T29: 2.21 | U29: 919.36 | V29: 0 | X29: 20260406 | Z29: DEBITO | AA29: 3908900 | AB29: BBVA | AE29: 0.77372685 | AF29: HONOR MALL DEL SUR | AG29: BBVA | AN29: =+AN28+1 -> 46110
A30: 1044162 | B30: VA | C30: A | D30: 46114 | E30: 46114 | G30: 871 | H30: PS0002 | I30: 3048 | J30: 949814 | L30: 455170******2123 | M30: Nac | N30: COM | O30: 46114 | P30: 1149 | Q30: Abonado | R30: 33.21 | S30: 14.83 | T30: 2.67 | U30: 1113.12 | V30: 0 | X30: 20260406 | Z30: DEBITO | AA30: 3908900 | AB30: BBVA | AE30: 0.77960648 | AF30: HONOR MALL DEL SUR | AG30: BBVA | AN30: =+AN29+1 -> 46111
A31: 1044162 | B31: VA | C31: A | D31: 46114 | E31: 46114 | G31: 871 | H31: PS0002 | I31: 3050 | J31: 9535 | L31: 428076******1097 | M31: Nac | N31: COM | O31: 46114 | P31: 69 | Q31: Abonado | R31: 1.99 | S31: 0.26 | T31: 0.05 | U31: 66.96 | V31: 0 | X31: 20260406 | Z31: CREDITO | AA31: 3908900 | AB31: BCP | AE31: 0.7930787 | AF31: HONOR MALL DEL SUR | AG31: BBVA | AN31: =+AN30+1 -> 46112
A32: 1044162 | B32: VA | C32: A | D32: 46114 | E32: 46114 | G32: 871 | H32: PS0002 | I32: 3052 | J32: 68960 | K32: 8 | L32: 447409******5476 | M32: Nac | N32: COM | O32: 46114 | P32: 1799 | Q32: Abonado | R32: 51.99 | S32: 14.21 | T32: 2.56 | U32: 1744.45 | V32: 0 | X32: 20260406 | Z32: CREDITO | AA32: 3908900 | AB32: BFALABELLA | AC32: NO | AE32: 0.80290509 | AF32: HONOR MALL DEL SUR | AG32: BBVA
A33: 1044162 | B33: VA | C33: A | D33: 46114 | E33: 46114 | G33: 871 | H33: PS0002 | I33: 3054 | J33: 304168 | L33: 454775******2975 | M33: Nac | N33: COM | O33: 46114 | P33: 1799 | Q33: Abonado | R33: 51.99 | S33: 14.21 | T33: 2.56 | U33: 1744.45 | V33: 0 | X33: 20260406 | Z33: CREDITO | AA33: 3908900 | AB33: IBK PRIVADA | AE33: 0.81288194 | AF33: HONOR MALL DEL SUR | AG33: BBVA
A34: 1044162 | B34: VA | C34: A | D34: 46114 | E34: 46114 | G34: 871 | H34: PS0002 | I34: 3056 | J34: 481828 | L34: 455788******7557 | M34: Nac | N34: COM | O34: 46114 | P34: 1799 | Q34: Abonado | R34: 51.99 | S34: 23.21 | T34: 4.18 | U34: 1742.83 | V34: 0 | X34: 20260406 | Z34: DEBITO | AA34: 3908900 | AB34: BCP | AE34: 0.82046296 | AF34: HONOR MALL DEL SUR | AG34: BBVA
A35: 1044162 | B35: VA | C35: A | D35: 46114 | E35: 46114 | G35: 871 | H35: PS0002 | I35: 3058 | J35: 132397 | L35: 428582******4884 | M35: Nac | N35: COM | O35: 46114 | P35: 1799 | Q35: Abonado | R35: 51.99 | S35: 23.21 | T35: 4.18 | U35: 1742.83 | V35: 0 | X35: 20260406 | Z35: DEBITO | AA35: 3908900 | AB35: SCOTIABANK | AE35: 0.82751157 | AF35: HONOR MALL DEL SUR | AG35: BBVA
A36: 1044162 | B36: VA | C36: A | D36: 46114 | E36: 46114 | G36: 871 | H36: PS0002 | I36: 3060 | J36: 617661 | L36: 455788******0642 | M36: Nac | N36: COM | O36: 46114 | P36: 499 | Q36: Abonado | R36: 14.42 | S36: 6.44 | T36: 1.16 | U36: 483.42 | V36: 0 | X36: 20260406 | Z36: DEBITO | AA36: 3908900 | AB36: BCP | AE36: 0.87384259 | AF36: HONOR MALL DEL SUR | AG36: BBVA
A37: 1044162 | B37: VA | C37: A | D37: 46114 | E37: 46114 | G37: 871 | H37: PS0002 | I37: 3062 | J37: 611910 | L37: 455788******6060 | M37: Nac | N37: COM | O37: 46114 | P37: 1149 | Q37: Abonado | R37: 33.21 | S37: 14.83 | T37: 2.67 | U37: 1113.12 | V37: 0 | X37: 20260406 | Z37: DEBITO | AA37: 3908900 | AB37: BCP | AE37: 0.87663194 | AF37: HONOR MALL DEL SUR | AG37: BBVA
A38: 1044162 | B38: VA | C38: A | D38: 46114 | E38: 46114 | G38: 871 | H38: 65656565 | I38: 3064 | J38: 122082 | L38: 427158******3689 | M38: Nac | N38: COM | O38: 46114 | P38: 125.8 | Q38: Abonado | R38: 3.63 | S38: 1.62 | T38: 0.29 | U38: 121.88 | V38: 0 | X38: 20260406 | Z38: DEBITO | AA38: 3908900 | AB38: SCOTIABANK | AD38: SBK Plin | AE38: 0.88900463 | AF38: HONOR MALL DEL SUR | AG38: BBVA
A39: 1044162 | B39: VA | C39: A | D39: 46114 | E39: 46114 | G39: 871 | H39: PS0002 | I39: 3067 | J39: 650498 | L39: 455788******2457 | M39: Nac | N39: COM | O39: 46114 | P39: 1699 | Q39: Abonado | R39: 49.1 | S39: 21.92 | T39: 3.95 | U39: 1645.95 | V39: 0 | X39: 20260406 | Z39: DEBITO | AA39: 3908900 | AB39: BCP | AE39: 0.89335648 | AF39: HONOR MALL DEL SUR | AG39: BBVA
A40: 1044162 | B40: VA | C40: A | D40: 46114 | E40: 46114 | G40: 871 | H40: PS0002 | I40: 3069 | J40: 519375 | L40: 455170******7910 | M40: Nac | N40: COM | O40: 46114 | P40: 688 | Q40: Abonado | R40: 19.88 | S40: 8.87 | T40: 1.6 | U40: 666.52 | V40: 0 | X40: 20260406 | Z40: DEBITO | AA40: 3908900 | AB40: BBVA | AE40: 0.89748843 | AF40: HONOR MALL DEL SUR | AG40: BBVA
...

Sheet AMEX
A1: Codigo | B1: Producto | C1: Tipo_Mov | D1: Fecha_Proceso | E1: Fecha_Lote | F1: Lote_Manual | G1: Lote_Pos | H1: Terminal | I1: Voucher | J1: Autorizacion | K1: Cuotas | L1: Tarjeta | M1: Origen | N1: Transaccion | O1: Fecha_Consumo | P1: Importe | Q1: Comision | R1: Comision_Merchant | S1: IGV | T1: Neto_Parcial | U1: Neto_Total | V1: Fecha_Abono | W1: Observaciones | X1: TIENDA | Y1: BANCOS | AB1: Etiquetas de fila | AC1: Suma de Importe
A2: 1044162 | C2: A | D2: 46113 | E2: 46113 | G2: 870 | H2: PS0002 | I2: 2990 | J2: 232578 | L2: 377892*****0738 | N2: COMPRA | O2: 46113 | P2: 459 | Q2: 18.31 | R2: 3.66 | S2: 0.66 | T2: 440.03 | U2: 0 | V2: 20260407 | X2: HONOR MALL DEL SUR | Y2: BBVA | AB2: 46113 | AC2: 459 | AH2: 46082 | AI2: 459
A3: 1044162 | C3: C | D3: 46113 | E3: 46113 | F3: 9996 | N3: S.E.A. | O3: 46113 | P3: 0 | Q3: -5 | R3: -5 | S3: -0.9 | T3: -5.9 | U3: 0 | V3: 20260407 | W3: Descuento Pendiente | X3: HONOR MALL DEL SUR | Y3: BBVA | AB3: 46114 | AC3: 3247 | AH3: =+AH2+1 -> 46083 | AI3: 3247
A4: 1044162 | C4: A | D4: 46113 | P4: 0 | Q4: 0 | R4: 0 | S4: 0 | T4: -5.9 | U4: 434.13 | V4: 20260407 | W4: 104101 | X4: HONOR MALL DEL SUR | Y4: BBVA | AB4: 46115 | AC4: 587 | AH4: =+AH3+1 -> 46084 | AI4: 587
A5: 1044162 | C5: A | D5: 46114 | E5: 46114 | G5: 871 | H5: PS0002 | I5: 3011 | J5: 662867 | L5: 377892*****9629 | N5: COMPRA | O5: 46114 | P5: 1248 | Q5: 49.8 | R5: 9.96 | S5: 1.79 | T5: 1196.41 | U5: 0 | V5: 20260407 | X5: HONOR MALL DEL SUR | Y5: BBVA | AB5: 46119 | AC5: 1399 | AH5: =+AH4+1 -> 46085
A6: 1044162 | C6: A | D6: 46114 | E6: 46114 | G6: 871 | H6: PS0002 | I6: 3013 | J6: 253782 | L6: 377754*****8286 | N6: COMPRA | O6: 46114 | P6: 1999 | Q6: 79.76 | R6: 15.95 | S6: 2.87 | T6: 1916.37 | U6: 3112.78 | V6: 20260407 | W6: 104101 | X6: HONOR MALL DEL SUR | Y6: BBVA | AB6: 46122 | AC6: 2148 | AH6: =+AH5+1 -> 46086
A7: 1044162 | C7: A | D7: 46115 | E7: 46115 | G7: 872 | H7: PS0002 | I7: 3117 | J7: 802638 | L7: 377933*****5047 | N7: COMPRA | O7: 46115 | P7: 498 | Q7: 22.16 | R7: 14.69 | S7: 2.64 | T7: 473.2 | U7: 0 | V7: 20260407 | X7: HONOR MALL DEL SUR | Y7: BBVA | AB7: 46123 | AC7: 1399 | AH7: =+AH6+1 -> 46087
A8: 1044162 | C8: A | D8: 46115 | E8: 46115 | G8: 872 | H8: PS0002 | I8: 3121 | J8: 394561 | L8: 377754*****1086 | N8: COMPRA | O8: 46115 | P8: 89 | Q8: 3.55 | R8: 0.71 | S8: 0.13 | T8: 85.32 | U8: 558.52 | V8: 20260407 | W8: 104101 | X8: HONOR MALL DEL SUR | Y8: BBVA | AB8: 46130 | AC8: 8998 | AH8: =+AH7+1 -> 46088 | AI8: 1399
A9: 1044162 | C9: A | D9: 46119 | E9: 46119 | G9: 876 | H9: PS0002 | I9: 3383 | J9: 163256 | K9: 2 | L9: 377754*****3034 | N9: COMPRA | O9: 46119 | P9: 1399 | Q9: 55.82 | R9: 11.16 | S9: 2.01 | T9: 1341.17 | U9: 1341.17 | V9: 20260409 | W9: 104101 | X9: HONOR MALL DEL SUR | Y9: BBVA | AB9: (en blanco) | AC9: 0 | AH9: =+AH8+1 -> 46089
A10: 1044162 | C10: A | D10: 46122 | E10: 46122 | G10: 879 | H10: PS0002 | I10: 3539 | J10: 495280 | L10: 377753*****6779 | N10: COMPRA | O10: 46122 | P10: 149 | Q10: 5.95 | R10: 1.19 | S10: 0.21 | T10: 142.84 | U10: 0 | V10: 20260414 | X10: HONOR MALL DEL SUR | Y10: BBVA | AB10: Total general | AC10: 18237 | AH10: =+AH9+1 -> 46090
A11: 1044162 | C11: A | D11: 46122 | E11: 46122 | G11: 879 | H11: PS0002 | I11: 3574 | J11: 306143 | K11: 6 | L11: 377898*****5559 | N11: COMPRA | O11: 46122 | P11: 1999 | Q11: 79.76 | R11: 15.95 | S11: 2.87 | T11: 1916.37 | U11: 2059.21 | V11: 20260414 | W11: 104101 | X11: HONOR MALL DEL SUR | Y11: BBVA | AH11: =+AH10+1 -> 46091 | AI11: 2148
A12: 1044162 | C12: A | D12: 46123 | E12: 46123 | G12: 880 | H12: PS0002 | I12: 3699 | J12: 382666 | K12: 3 | L12: 377754*****1538 | N12: COMPRA | O12: 46123 | P12: 1399 | Q12: 55.82 | R12: 11.16 | S12: 2.01 | T12: 1341.17 | U12: 1341.17 | V12: 20260414 | W12: 104101 | X12: HONOR MALL DEL SUR | Y12: BBVA | AH12: =+AH11+1 -> 46092 | AI12: 1399
A13: 1044162 | C13: A | D13: 46130 | E13: 46130 | G13: 887 | H13: PS0002 | I13: 4053 | J13: 359311 | K13: 2 | L13: 377897*****8372 | N13: COMPRA | O13: 46130 | P13: 3999 | Q13: 159.56 | R13: 31.91 | S13: 5.74 | T13: 3833.7 | U13: 0 | V13: 20260421 | X13: HONOR MALL DEL SUR | Y13: BBVA | AH13: =+AH12+1 -> 46093
A14: 1044162 | C14: A | D14: 46130 | E14: 46130 | G14: 887 | H14: PS0002 | I14: 4070 | J14: 139381 | L14: 377892*****2080 | N14: COMPRA | O14: 46130 | P14: 4999 | Q14: 199.46 | R14: 39.89 | S14: 7.18 | T14: 4792.36 | U14: 8626.06 | V14: 20260421 | W14: 104101 | X14: HONOR MALL DEL SUR | Y14: BBVA | AH14: =+AH13+1 -> 46094
A15: 1044162 | C15: A | D15: 46131 | E15: 46131 | G15: 888 | H15: PS0002 | I15: 4081 | J15: 659602 | L15: 377892*****3559 | N15: COMPRA | O15: 46131 | P15: 1799 | Q15: 71.78 | R15: 14.36 | S15: 2.58 | T15: 1724.64 | U15: 0 | V15: 20260421 | X15: HONOR MALL DEL SUR | Y15: BBVA | AH15: =+AH14+1 -> 46095
A16: 1044162 | C16: A | D16: 46131 | E16: 46131 | G16: 888 | H16: PS0002 | I16: 4115 | J16: 132073 | L16: 377754*****9756 | N16: COMPRA | O16: 46131 | P16: 629 | Q16: 25.1 | R16: 5.02 | S16: 0.9 | T16: 603 | U16: 0 | V16: 20260421 | X16: HONOR MALL DEL SUR | Y16: BBVA | AH16: =+AH15+1 -> 46096
A17: 1044162 | C17: A | D17: 46131 | E17: 46131 | G17: 888 | H17: PS0002 | I17: 4149 | J17: 385262 | K17: 12 | L17: 377752*****7034 | N17: COMPRA | O17: 46131 | P17: 1799 | Q17: 71.78 | R17: 14.36 | S17: 2.58 | T17: 1724.64 | U17: 4052.28 | V17: 20260421 | W17: 104101 | X17: HONOR MALL DEL SUR | Y17: BBVA | AH17: =+AH16+1 -> 46097
AH18: =+AH17+1 -> 46098
AH19: =+AH18+1 -> 46099 | AI19: 8998
AH20: =+AH19+1 -> 46100
AH21: =+AH20+1 -> 46101
AH22: =+AH21+1 -> 46102
AH23: =+AH22+1 -> 46103
AH24: =+AH23+1 -> 46104
AH25: =+AH24+1 -> 46105
AH26: =+AH25+1 -> 46106
AH27: =+AH26+1 -> 46107
AH28: =+AH27+1 -> 46108
AH29: =+AH28+1 -> 46109
AH30: =+AH29+1 -> 46110
AH31: =+AH30+1 -> 46111
AH32: =+AH31+1 -> 46112

Sheet DINNERS
A1: Código de comercio | B1: Nombre del comercio | C1: Red | D1: Origen | E1: Tipo de transacción | F1: Fecha de recepción | G1: Fecha de proceso | H1: Marca | I1: N° de tarjeta | J1: Tipo de tarjeta | K1: Código de autorización | L1: Orden de pago | M1: Moneda | N1: Fecha de ticket | O1: N° ticket | P1: Estado de ticket | Q1: N° de cuotas | R1: Plazo de pago | S1: Fecha de pago | T1: Tipo de comisión | U1: Valor de comisión | V1: Importe del consumo | W1: Comisión del consumo | X1: IGV del consumo | Y1: Importe neto de pago | Z1: Producto | AC1: Etiquetas de fila | AD1: Suma de Importe del consumo
A2: 2000389606 | B2: HONOR MALL DEL SUR | C2: IZIPAY | E2: CONSUMO | F2: 46126 | G2: 46126 | H2: DINERS | I2: **** ****** 1941 | J2: LOCAL | K2: 38147 | L2: 2.60416e+15 | M2: SOLES | N2: 46125 | O2: 3842 | P2: PROCESADO | Q2: 3 | R2: 2 días | S2: 46128 | T2: PORCENTUAL | U2: 3.95 | V2: 89 | W2: 3.52 | X2: 0.63 | Y2: 84.85 | Z2: CUOTAS SIN INTERESES | AC2: (en blanco) | AH2: 46082
A3: 2000389606 | B3: HONOR MALL DEL SUR | C3: IZIPAY | E3: CONSUMO | F3: 46110 | G3: 46110 | H3: DINERS | I3: **** ****** 6993 | J3: LOCAL | K3: 19507 | L3: 2.60331e+15 | M3: SOLES | N3: 46109 | O3: 2645 | P3: PROCESADO | Q3: 3 | R3: 2 días | S3: 46112 | T3: PORCENTUAL | U3: 3.95 | V3: 898 | W3: 35.47 | X3: 6.38 | Y3: 856.15 | Z3: CUOTAS SIN INTERESES | AC3: 46125 | AD3: 89 | AH3: =+AH2+1 -> 46083
A4: 2000389606 | B4: HONOR MALL DEL SUR | C4: IZIPAY | E4: CONSUMO | F4: 46109 | G4: 46109 | H4: DINERS | I4: **** ****** 6993 | J4: LOCAL | K4: 73303 | L4: 2.6033e+15 | M4: SOLES | N4: 46108 | O4: 2572 | P4: PROCESADO | Q4: 3 | R4: 2 días | S4: 46111 | T4: PORCENTUAL | U4: 3.95 | V4: 898 | W4: 35.47 | X4: 6.38 | Y4: 856.15 | Z4: CUOTAS SIN INTERESES | AC4: 46109 | AD4: 898 | AH4: =+AH3+1 -> 46084
A5: 2000389606 | B5: HONOR MALL DEL SUR | C5: IZIPAY | E5: CONSUMO | F5: 46106 | G5: 46106 | H5: DINERS | I5: **** ****** 1764 | J5: LOCAL | K5: 69619 | L5: 2.60327e+15 | M5: SOLES | N5: 46105 | O5: 2441 | P5: PROCESADO | Q5: 3 | R5: 2 días | S5: 46108 | T5: PORCENTUAL | U5: 3.95 | V5: 899 | W5: 35.51 | X5: 6.39 | Y5: 857.1 | Z5: CUOTAS SIN INTERESES | AC5: 46108 | AD5: 898 | AH5: =+AH4+1 -> 46085
AC6: 46105 | AD6: 899 | AH6: =+AH5+1 -> 46086
AC7: Total general | AD7: 2784 | AH7: =+AH6+1 -> 46087
AH8: =+AH7+1 -> 46088
AH9: =+AH8+1 -> 46089
AH10: =+AH9+1 -> 46090
AH11: =+AH10+1 -> 46091
AH12: =+AH11+1 -> 46092
AH13: =+AH12+1 -> 46093
AH14: =+AH13+1 -> 46094 | AI14: 89
AH15: =+AH14+1 -> 46095
AH16: =+AH15+1 -> 46096
AH17: =+AH16+1 -> 46097
AH18: =+AH17+1 -> 46098
AH19: =+AH18+1 -> 46099
AH20: =+AH19+1 -> 46100
AH21: =+AH20+1 -> 46101
AH22: =+AH21+1 -> 46102
AH23: =+AH22+1 -> 46103
AH24: =+AH23+1 -> 46104
AH25: =+AH24+1 -> 46105
AH26: =+AH25+1 -> 46106
... AH32: =+AH31+1 -> 46112
